ERROR 2022-10-15 20:00:58,717 Internal Server Error: /news/create/ E:\Python\DjangoProject\venv\lib\site-packages\django\utils\log.py (<class 'django.db.utils.IntegrityError'>, IntegrityError('NOT NULL constraint failed: news_post.author_id'), <traceback object at 0x000002400B034480>)
Traceback (most recent call last):
  File "E:\Python\DjangoProject\venv\lib\site-packages\django\db\backends\utils.py", line 89, in _execute
    return self.cursor.execute(sql, params)
  File "E:\Python\DjangoProject\venv\lib\site-packages\django\db\backends\sqlite3\base.py", line 357, in execute
    return Database.Cursor.execute(self, query, params)
sqlite3.IntegrityError: NOT NULL constraint failed: news_post.author_id

The above exception was the direct cause of the following exception:

Traceback (most recent call last):
  File "E:\Python\DjangoProject\venv\lib\site-packages\django\core\handlers\exception.py", line 55, in inner
    response = get_response(request)
  File "E:\Python\DjangoProject\venv\lib\site-packages\django\core\handlers\base.py", line 197, in _get_response
    response = wrapped_callback(request, *callback_args, **callback_kwargs)
  File "E:\Python\DjangoProject\venv\lib\site-packages\django\views\generic\base.py", line 103, in view
    return self.dispatch(request, *args, **kwargs)
  File "E:\Python\DjangoProject\venv\lib\site-packages\django\contrib\auth\mixins.py", line 73, in dispatch
    return super().dispatch(request, *args, **kwargs)
  File "E:\Python\DjangoProject\venv\lib\site-packages\django\contrib\auth\mixins.py", line 109, in dispatch
    return super().dispatch(request, *args, **kwargs)
  File "E:\Python\DjangoProject\venv\lib\site-packages\django\views\generic\base.py", line 142, in dispatch
    return handler(request, *args, **kwargs)
  File "E:\Python\DjangoProject\News_VVS\news\views.py", line 150, in post
    post_mail.save()
  File "E:\Python\DjangoProject\venv\lib\site-packages\django\db\models\base.py", line 831, in save
    self.save_base(
  File "E:\Python\DjangoProject\venv\lib\site-packages\django\db\models\base.py", line 882, in save_base
    updated = self._save_table(
  File "E:\Python\DjangoProject\venv\lib\site-packages\django\db\models\base.py", line 1025, in _save_table
    results = self._do_insert(
  File "E:\Python\DjangoProject\venv\lib\site-packages\django\db\models\base.py", line 1066, in _do_insert
    return manager._insert(
  File "E:\Python\DjangoProject\venv\lib\site-packages\django\db\models\manager.py", line 85, in manager_method
    return getattr(self.get_queryset(), name)(*args, **kwargs)
  File "E:\Python\DjangoProject\venv\lib\site-packages\django\db\models\query.py", line 1790, in _insert
    return query.get_compiler(using=using).execute_sql(returning_fields)
  File "E:\Python\DjangoProject\venv\lib\site-packages\django\db\models\sql\compiler.py", line 1657, in execute_sql
    cursor.execute(sql, params)
  File "E:\Python\DjangoProject\venv\lib\site-packages\django\db\backends\utils.py", line 103, in execute
    return super().execute(sql, params)
  File "E:\Python\DjangoProject\venv\lib\site-packages\django\db\backends\utils.py", line 67, in execute
    return self._execute_with_wrappers(
  File "E:\Python\DjangoProject\venv\lib\site-packages\django\db\backends\utils.py", line 80, in _execute_with_wrappers
    return executor(sql, params, many, context)
  File "E:\Python\DjangoProject\venv\lib\site-packages\django\db\backends\utils.py", line 89, in _execute
    return self.cursor.execute(sql, params)
  File "E:\Python\DjangoProject\venv\lib\site-packages\django\db\utils.py", line 91, in __exit__
    raise dj_exc_value.with_traceback(traceback) from exc_value
  File "E:\Python\DjangoProject\venv\lib\site-packages\django\db\backends\utils.py", line 89, in _execute
    return self.cursor.execute(sql, params)
  File "E:\Python\DjangoProject\venv\lib\site-packages\django\db\backends\sqlite3\base.py", line 357, in execute
    return Database.Cursor.execute(self, query, params)
django.db.utils.IntegrityError: NOT NULL constraint failed: news_post.author_id
ERROR 2022-10-15 20:00:58,720 "POST /news/create/ HTTP/1.1" 500 184287 E:\Python\DjangoProject\venv\lib\site-packages\django\core\servers\basehttp.py None
ERROR 2022-10-15 20:26:25,748 Internal Server Error: /sign/upgrade/ E:\Python\DjangoProject\venv\lib\site-packages\django\utils\log.py (<class 'NameError'>, NameError("name 'Author' is not defined"), <traceback object at 0x00000271243C7C40>)
Traceback (most recent call last):
  File "E:\Python\DjangoProject\venv\lib\site-packages\django\core\handlers\exception.py", line 55, in inner
    response = get_response(request)
  File "E:\Python\DjangoProject\venv\lib\site-packages\django\core\handlers\base.py", line 197, in _get_response
    response = wrapped_callback(request, *callback_args, **callback_kwargs)
  File "E:\Python\DjangoProject\venv\lib\site-packages\django\contrib\auth\decorators.py", line 23, in _wrapped_view
    return view_func(request, *args, **kwargs)
  File "E:\Python\DjangoProject\News_VVS\sign\views.py", line 14, in upgrade_me
    Author.objects.create(authorUser=user)
NameError: name 'Author' is not defined
ERROR 2022-10-15 20:26:25,749 "GET /sign/upgrade/ HTTP/1.1" 500 79721 E:\Python\DjangoProject\venv\lib\site-packages\django\core\servers\basehttp.py None
ERROR 2022-10-15 21:27:43,122 Internal Server Error: / E:\Python\DjangoProject\venv\lib\site-packages\django\utils\log.py (<class 'django.template.exceptions.TemplateSyntaxError'>, TemplateSyntaxError("Invalid block tag on line 14: 'Author.objects.create(authorUser=request.user.all())', expected 'elif', 'else' or 'endif'. Did you forget to register or load this tag?"), <traceback object at 0x0000018F45096B40>)
Traceback (most recent call last):
  File "E:\Python\DjangoProject\venv\lib\site-packages\django\template\base.py", line 505, in parse
    compile_func = self.tags[command]
KeyError: 'Author.objects.create(authorUser=request.user.all())'

During handling of the above exception, another exception occurred:

Traceback (most recent call last):
  File "E:\Python\DjangoProject\venv\lib\site-packages\django\core\handlers\exception.py", line 55, in inner
    response = get_response(request)
  File "E:\Python\DjangoProject\venv\lib\site-packages\django\core\handlers\base.py", line 220, in _get_response
    response = response.render()
  File "E:\Python\DjangoProject\venv\lib\site-packages\django\template\response.py", line 114, in render
    self.content = self.rendered_content
  File "E:\Python\DjangoProject\venv\lib\site-packages\django\template\response.py", line 90, in rendered_content
    template = self.resolve_template(self.template_name)
  File "E:\Python\DjangoProject\venv\lib\site-packages\django\template\response.py", line 72, in resolve_template
    return select_template(template, using=self.using)
  File "E:\Python\DjangoProject\venv\lib\site-packages\django\template\loader.py", line 42, in select_template
    return engine.get_template(template_name)
  File "E:\Python\DjangoProject\venv\lib\site-packages\django\template\backends\django.py", line 34, in get_template
    return Template(self.engine.get_template(template_name), self)
  File "E:\Python\DjangoProject\venv\lib\site-packages\django\template\engine.py", line 175, in get_template
    template, origin = self.find_template(template_name)
  File "E:\Python\DjangoProject\venv\lib\site-packages\django\template\engine.py", line 157, in find_template
    template = loader.get_template(name, skip=skip)
  File "E:\Python\DjangoProject\venv\lib\site-packages\django\template\loaders\cached.py", line 57, in get_template
    template = super().get_template(template_name, skip)
  File "E:\Python\DjangoProject\venv\lib\site-packages\django\template\loaders\base.py", line 28, in get_template
    return Template(
  File "E:\Python\DjangoProject\venv\lib\site-packages\django\template\base.py", line 154, in __init__
    self.nodelist = self.compile_nodelist()
  File "E:\Python\DjangoProject\venv\lib\site-packages\django\template\base.py", line 200, in compile_nodelist
    return parser.parse()
  File "E:\Python\DjangoProject\venv\lib\site-packages\django\template\base.py", line 513, in parse
    raise self.error(token, e)
  File "E:\Python\DjangoProject\venv\lib\site-packages\django\template\base.py", line 511, in parse
    compiled_result = compile_func(self, token)
  File "E:\Python\DjangoProject\venv\lib\site-packages\django\template\loader_tags.py", line 293, in do_extends
    nodelist = parser.parse()
  File "E:\Python\DjangoProject\venv\lib\site-packages\django\template\base.py", line 513, in parse
    raise self.error(token, e)
  File "E:\Python\DjangoProject\venv\lib\site-packages\django\template\base.py", line 511, in parse
    compiled_result = compile_func(self, token)
  File "E:\Python\DjangoProject\venv\lib\site-packages\django\template\loader_tags.py", line 232, in do_block
    nodelist = parser.parse(("endblock",))
  File "E:\Python\DjangoProject\venv\lib\site-packages\django\template\base.py", line 513, in parse
    raise self.error(token, e)
  File "E:\Python\DjangoProject\venv\lib\site-packages\django\template\base.py", line 511, in parse
    compiled_result = compile_func(self, token)
  File "E:\Python\DjangoProject\venv\lib\site-packages\django\template\defaulttags.py", line 954, in do_if
    nodelist = parser.parse(("elif", "else", "endif"))
  File "E:\Python\DjangoProject\venv\lib\site-packages\django\template\base.py", line 507, in parse
    self.invalid_block_tag(token, command, parse_until)
  File "E:\Python\DjangoProject\venv\lib\site-packages\django\template\base.py", line 558, in invalid_block_tag
    raise self.error(
django.template.exceptions.TemplateSyntaxError: Invalid block tag on line 14: 'Author.objects.create(authorUser=request.user.all())', expected 'elif', 'else' or 'endif'. Did you forget to register or load this tag?
ERROR 2022-10-15 21:27:43,124 "GET / HTTP/1.1" 500 190910 E:\Python\DjangoProject\venv\lib\site-packages\django\core\servers\basehttp.py None
